File: value_stream_data_converted.csv
Cutting Time (s),Cutting Speed (m/min),Feed Rate (mm/rev),Notch Wear (mm),Depth of Cut (mm),Plastic Deformation (mm),Flank Wear (mm),Crater Wear (mm),Surface Finish (µm),Tool Temperature (°C),Stress (MPa),Chip Formation (type),Machine Failure Rate
21.201265531738976,108.38928745111085,0.2655589789209034,0.03438077556043958,1.1575109348007342,0.09370927271862922,0.4511004544589559,0.09349620456274384,0.1659128466785747,426.07037360621473,389.2796671335536,2,0
58.403759474020134,126.228240117709,0.18943946936655426,0.11087312514047133,1.779601040361175,0.07540039259165093,0.3743169863597746,0.330259240918213,0.797599958862454,208.04497582582576,476.406168852275,1,0
46.11040694707204,320.80400052309517,0.2932750600287243,0.049090449665981306,1.77805080138929,0.04681508530697029,0.34692735026874644,0.28336453112790283,0.5338823479897209,780.8847507966796,124.91652499029705,1,0
149.2615863089632,448.2000858220221,0.41605339803256414,0.15369987785035105,9.859826214705443,0.06752025831912435,0.25810671028628385,0.28857392688241784,1.8294105227285742,809.8687154731808,348.6888569278722,2,0
16.141088746086254,343.1538041731102,0.4582638931699705,0.09329062067662966,8.993923111373011,0.08456474724849034,0.3170797036191934,0.1982341433256626,1.6970869837299554,954.4476323345777,972.0800413551385,2,0
203.04974022100373,352.3998823858143,0.16496799305259446,0.14180370494430553,3.8688848686041353,0.013596502848597808,0.08284649797941028,0.03168029832091145,1.493156376127088,574.8722159616924,662.902168613226,1,0
173.47980267396494,158.37092720056808,0.4286410306140809,0.10725239989017869,2.3598491063897193,0.031287581307996026,0.3193895106679451,0.24841814886456742,1.0164317461723682,276.8933265363711,903.0044076416625,3,0
290.64472820522235,168.71329736173294,0.36401349278084616,0.08057578720584933,3.33920611379611,0.04435949091675055,0.062214823027622775,0.29205726669567333,0.39226052573414616,418.00820279784733,781.5927238934803,2,0
46.15534002715197,297.16910824050274,0.11014459039531173,0.1038542931848187,7.996180512135474,0.06319972746801032,0.4004670667980044,0.0676531823511934,0.3901091617812399,225.48254855189907,193.4530301618837,3,0
97.46648392550269,66.55292578530529,0.4659288535009892,0.13831203962818223,0.8109201403426677,0.08413297160535194,0.17606085358375081,0.07977561235937293,0.6821882153789006,800.5288115741052,950.159973195497,1,0
56.42872589750308,102.46571572589139,0.3348305195203837,0.016164158960522295,8.258286062487588,0.051310222338377585,0.07995188993666794,0.23865360039518738,0.7257510560446256,733.9481169689373,704.8028994924414,3,0
278.3878060393242,479.0254218107513,0.3592843098764904,0.15845445351103618,3.2884814900629102,0.07983273579103167,0.42833424693997885,0.09851826810752186,1.2347699285838267,377.28219023267036,53.644904075785654,2,0
61.20545291300236,298.8620761286154,0.13343763914781293,0.14567065382166478,9.567223156975054,0.09678013135941232,0.22718019830421746,0.3955912029207635,0.4435630435625213,255.8117879605544,374.7635185404732,1,0
258.3988403931292,379.12262071173524,0.4061379597730751,0.1212852538816742,8.742187100823315,0.06381002046326414,0.2763362396997376,0.12199680607516489,0.9102992941838373,450.72322595757123,104.29713028041778,2,0
214.03200664265415,106.81354225006868,0.25250226660161557,0.08914108244891833,5.870355152414338,0.06559441464006663,0.48918718123749466,0.2588833382630315,1.6581134423944017,665.5961528883713,106.73078952106458,1,0
284.65633792043855,71.77634666550468,0.46729806014759,0.09237053499027283,6.546832046229311,0.05509503565837902,0.17066930597337107,0.2581474470641034,1.6659571322138587,384.35067242522484,432.48399513856833,2,0
129.09555680674134,244.35899736308133,0.42295487800941545,0.1889897035345013,3.528256078492959,0.019941732028502232,0.024089560348547888,0.2454448728964645,0.3244709565192713,873.9811757036877,597.5868057924723,2,0
141.9801090657716,85.08243230382391,0.1624537506579738,0.14188269308012416,7.602769700514369,0.01975196600490335,0.16079323681277943,0.012767172311495541,1.222906624437306,582.3847946127688,254.37500433126536,2,0
167.60755021823473,466.61049597036003,0.36413033801052064,0.18273298286659345,3.5953637161274967,0.05225955402530955,0.02511125246267204,0.25842443377530305,1.1184224216816987,310.73353422946593,530.4579612851483,2,0
118.05331079229428,321.8838634751122,0.19452939238123967,0.11019600910639603,9.16006313154929,0.03468590776443061,0.0477896391472169,0.3256024576224673,0.7671343155000344,717.8185553472234,305.0877262477186,1,0
82.91954831686351,493.29181178773956,0.4072910998832119,0.051337843907334826,1.6599583550926553,0.07594424039653026,0.2699697597702245,0.3195735063464156,1.6538262059955375,521.4769659289609,391.59278367462696,1,0
99.97444898095414,147.76499935847045,0.26863989255173126,0.02522766040962045,3.2304048891813717,0.06391036036323418,0.3556185955416399,0.1325539392383085,0.9161574771545351,797.3815429564346,710.6947103416802,1,0
188.9551421244218,144.9990787179623,0.11183621109962485,0.015687726880497993,4.144403911184233,0.060397654774783344,0.24884957556912585,0.1268126189153324,1.469169590251162,430.4580474056661,936.7863892725368,3,0
224.3274152323326,229.88511774996573,0.3483057909376548,0.07889183683177191,3.4345712295727107,0.09367261172044818,0.03702409074598475,0.3931408172749297,0.17197923845995372,982.3183162647547,857.0866882461155,1,1
153.823898069727,202.78751586443047,0.4704764739952597,0.06380960801263069,3.802001404672865,0.05701239025079506,0.13844118873870181,0.3171110108723876,1.111876014956262,843.1641848072006,720.7256168576833,1,0
139.26491606334832,114.94346958013747,0.49631906030883954,0.0561417530809883,8.655603805227937,0.045860694471250005,0.39013139707755323,0.03217599666117118,1.8544363745755983,920.815227953637,55.53852701047434,1,0
137.4976723086219,67.40434655843691,0.2208043488499384,0.07285488862796839,3.675254385182498,0.08803949145048118,0.03565118750323212,0.06900357034978283,1.7586991376721752,937.0197862475761,71.84704333187683,3,0
171.06690359861437,423.3995960110249,0.4972258770346286,0.15740219871592567,1.364707652585493,0.012854703566832357,0.46684984553454806,0.12623025804386276,1.2360974912081704,950.3022089555238,507.37875485031367,3,0
274.70357595446046,299.70040702695326,0.37602322547942535,0.027159831903838756,9.478260833850177,0.06874116495409262,0.19097081204742378,0.061756600415322035,1.6413469930845062,223.1487345417146,898.9872625682171,3,0
257.65505394187005,397.15594523925046,0.3593142937443278,0.13475462629329835,1.83061509163753,0.08388957205383521,0.4121581201548934,0.1286703873149876,1.2020427245398029,898.378874831374,763.3695386182962,3,0
24.929049653602938,148.2215148385655,0.45017087435707204,0.04000283324754313,2.244330037294641,0.09017400351666358,0.049993899943346694,0.054627668118429076,0.5613315479977996,591.0996628918299,225.0166364452633,3,0
11.529631593260275,153.11705702351964,0.1207973706275256,0.11370080919993585,5.508633706748366,0.036989934366753185,0.13545604224565483,0.25198888386151125,0.33188224220092255,900.022494150329,324.600073130176,2,0
48.61652552747063,448.4533260776958,0.19426664420029197,0.12639743872545015,7.405386719326612,0.07782996004617719,0.09197876055517225,0.1642686519668716,0.7506651759967283,335.95287193373713,712.1837091365697,2,1
298.73720157477754,482.1305301244162,0.27187575865263447,0.025703489351909227,8.089137859450641,0.07586268548830512,0.45928193462414585,0.08211847104036173,1.6375753306599685,885.5117802726144,641.0835846450422,2,0
246.43562751998167,151.32311661481071,0.3539541097968706,0.17387159822541526,8.670384190690662,0.0615791853179486,0.35836316143542324,0.2376412033017468,1.6751987698105555,659.6058701824206,102.11322793918275,1,0
19.35441033495482,316.3287436767912,0.4008009989291058,0.05587382428307722,8.79804400830287,0.055569869953747235,0.02721836667824388,0.39885397576155446,0.9330076314189052,947.3903354481495,534.1420904062131,2,0
133.9416666579943,366.7184951523203,0.40349227009107547,0.07500273801301136,9.768313619281036,0.06455994094961337,0.2604377885349812,0.328358872171159,1.1736067417102762,617.7484279379597,426.7135049429742,2,0
189.21513068967874,441.49829452104933,0.22754519715186305,0.1841933911847253,7.135236812851217,0.014444203943915773,0.012607018918908194,0.023868072065645306,0.9092719315767545,348.7698429563876,305.8435804295186,1,0
210.52771767069453,223.8240954651079,0.4108745727550446,0.05685878593825598,4.318627012665344,0.09408412822902615,0.04185339687391013,0.2812955305877013,0.9728102466153656,882.8642782721753,532.0871010115958,2,0
88.4239024370645,131.35725126931897,0.3379812280156794,0.13422911810626353,2.963507693370036,0.06515551636394609,0.4017609161177145,0.025059258443000047,1.6666491616429926,643.8328183541664,327.37586792988606,2,0
105.94530230875644,316.5412891550694,0.48993910174209143,0.017965145048159527,8.878545464531818,0.07586522856782398,0.24712701037345133,0.23903863248670468,1.4881310698120305,462.2541884290303,50.25387600586143,3,0
152.99986902653174,73.73490353140336,0.13187090950246103,0.03890171492415835,0.7316333762948052,0.0616197602903927,0.02072180734778202,0.1797614137111193,0.49347848646168624,506.04240840326094,674.07577589499,1,0
75.03372125679479,326.13567793114356,0.41732609111346175,0.09334989725232117,4.002121931600913,0.09397225922433886,0.43854870327238865,0.07524438745320496,1.8205996755075378,447.5563918858819,471.61174940071095,2,0
128.6656791380119,433.382573568292,0.21618876072196447,0.05288279285766304,7.525774730015686,0.07647226900358911,0.21493389494157994,0.08133438240511578,0.9343611902160057,503.00801337727785,582.928004973032,3,0
54.87383392336038,450.7096789337609,0.464601943008888,0.16990062206149795,5.656002192262381,0.022109800783324984,0.33261381263879014,0.2504832328476486,0.2902953469982002,638.5936531761542,342.16612605047396,1,0
251.241892268541,422.35434860537237,0.10562691424577048,0.01038538289248836,3.3701915515066534,0.05652210813243557,0.4302064934285843,0.3749768231135657,1.9452524577721004,291.2058934831993,324.8448699924149,2,0
263.5785227990193,377.9221377596399,0.11611107799654868,0.1420778424916743,9.254487891979478,0.07115431041844238,0.4825607123087985,0.05296020017625247,1.901577023169715,572.2910119826549,51.153466045903215,2,0
193.25805045417442,265.0808008666053,0.4938681437173198,0.1278266072460389,5.671972185668098,0.07894645921396598,0.05743065948346922,0.28181762014232836,0.27444903094518847,360.2262006085574,103.96196521494667,2,0
179.49264569670981,395.158565414219,0.27042265424230694,0.15936853508935497,9.42593731252463,0.09295870608878982,0.13153867251550708,0.18159220524864586,1.544832526889328,267.1690210806182,385.3941607890945,3,0
175.83754466170612,302.5158749741265,0.27632085696103403,0.09558264883387203,0.5067844777158017,0.028335590570305755,0.3284696275476309,0.2921525528147791,0.43880098927455213,420.8179006104622,227.52247655294212,1,0
99.52443098022508,241.71050403799467,0.2633715069927814,0.13042501258734562,7.7330457885397585,0.01627663526321512,0.4226084197023805,0.1501791465888976,0.8827431606314968,793.2154282421142,221.24532255338858,3,0
245.76711834911833,389.356321137094,0.1899602561632909,0.07385577879560201,5.00894150859133,0.043257118149578534,0.4685840730498573,0.1766849942442399,1.6941326540478467,989.2596114065873,505.08519507828606,3,0
185.74791374714928,269.98179338196377,0.1033090718130826,0.05314017147023582,1.3590398493074942,0.015713074275167146,0.25722896484499896,0.295757101283683,1.4610674766103442,760.9644720287013,969.3622057021431,2,0
107.19511462825321,396.96458953600086,0.14518582152885587,0.041118600240252115,1.2520977494043017,0.059567616001022755,0.14499178839622037,0.22826161055737287,1.492135093609091,996.0391145873008,351.83054573108103,3,0
285.89102777929105,103.94953267788816,0.10194696918501714,0.10315089757771868,0.7927478652080683,0.09463104953074927,0.12411877479201688,0.2855163923484726,1.4256668383533304,935.5181371737071,205.9042024499245,1,0
268.26039272785323,66.06553025963248,0.43108433807956203,0.13757984484467167,9.871033832196717,0.08850796162583156,0.3739969703175699,0.35305250739645705,1.6649271775331906,815.5929035840954,610.4636681468209,3,0
297.7118567105971,223.04140967810946,0.2116209686605549,0.12027857148747481,7.81945385444874,0.0756858722762236,0.48830354125389314,0.17204446990783784,1.7394728812200582,986.4427169057943,446.4825166738264,3,0
246.30178076250726,320.53713295932295,0.47114665342138573,0.020912022637839107,3.7455123984695096,0.06669967367454967,0.3586695268150685,0.2850296126552885,0.6261594687502022,724.2868605113076,812.742754000166,2,0
42.86520805167435,336.5575189571816,0.1910110362267591,0.013920314036345815,5.995885718239673,0.019853508558871365,0.09972183888348157,0.3909617697570545,0.7381435307611577,776.6349016865172,753.9670474611628,3,0
140.20935376379637,349.0297290670121,0.45873455578169875,0.02300332996663471,4.182588726185566,0.048814104830077795,0.3474536680627907,0.12477623614984715,0.5226676705340273,777.1690493750674,661.0472483550288,2,0
22.56287302765814,229.8096694113119,0.18694084785544784,0.03247980028369228,3.130068776357569,0.05938823938228022,0.047512307031654426,0.3880138443440429,1.2701055663510745,965.3536412081235,879.6381229675114,2,0
187.0170971274826,117.01665293911871,0.3028307052072934,0.021198422058623823,2.9322036609100763,0.016441175070825438,0.46970671040819206,0.35410253887526016,1.4708144842508892,965.3198174073443,694.3382145052286,3,0
81.55575845786488,71.49178354037349,0.49332317288343186,0.12310522446964854,1.9010921349489451,0.047074741820550894,0.11881678241223798,0.14603123920726482,0.7907738960727679,944.4175470820935,813.1499681327025,1,0
162.6632444111056,290.79322645524974,0.32635750625996246,0.07032118854253386,3.4039050257645314,0.05381044110634245,0.04110606271234828,0.06969102198887808,1.6029658632761368,774.8346969561309,315.6653441512473,1,0
196.78518641770435,97.69312260647476,0.3467853329639067,0.14312354975897926,8.61238464297231,0.0331623662007845,0.184427526919755,0.1422257009062258,0.2588140965607421,511.3413829408709,884.1097107878733,3,0
213.90920726726412,89.68965484639892,0.2666400776582361,0.054998677161660306,7.556273884886749,0.09740899885390575,0.45322537348264064,0.1854747083410338,1.3779752587426846,930.4022394731638,928.6913518403945,3,0
165.4737735236231,471.58380585180987,0.30590067811834787,0.13407553476362882,0.9980224896733283,0.08624794532466298,0.3781462283520883,0.13768435365587142,1.6112194004526685,611.9102164666435,792.5175647687128,2,0
114.28881717926424,119.5137876548577,0.18892599836131999,0.0826155278591721,3.499762232532158,0.02341937746635145,0.3632116541061679,0.3287695076452939,1.958100680721765,498.6079262871777,88.53617462105726,2,0
193.28169100256565,259.23649797236095,0.2072776018054494,0.08269532120408894,4.56440877847336,0.03199310553402106,0.09499182667220366,0.3853937486364185,0.30029476163341656,262.12973414577414,411.32963924916714,3,0
277.3470110357448,245.24013483908936,0.3632524444831463,0.18369107803925472,6.129417628845928,0.02669875385126534,0.22004265189295544,0.3894248239848118,1.7931400093506282,412.8182173530541,381.4893988992355,1,0
30.915656652820868,443.66100321623367,0.2941647289396663,0.11805430513646345,2.114282798236629,0.05126786261278395,0.40678256432256404,0.17766243972906667,1.4889341442680328,209.67073760596318,553.0781783758023,2,0
142.79154465294343,440.8466606256025,0.3589093643548865,0.14844248410921188,5.7546550574987165,0.03559623322311523,0.10513803086114391,0.010917827600956219,1.3150545486747731,826.4194994874322,302.4975047123474,1,0
17.217366929041166,54.12070829193601,0.3592764157368489,0.040853258321279486,1.0595290783905926,0.06389130874272991,0.4761714580937479,0.10541115696991914,1.5516181243903897,778.2103065633235,359.8849210111945,1,0
121.67643585143124,368.17602128303054,0.23093613759133041,0.03688999473076146,5.918352804553537,0.056967516249198866,0.1615285113338543,0.2565423933452661,0.1535516989175637,204.56111402679565,656.6597057536385,2,0
214.71045530405772,431.1935509043974,0.17929962930137916,0.03713951867325855,2.230781186913081,0.0994717063731236,0.44315665635944135,0.32544178545613794,0.7394928384400187,532.8841468520969,445.90295718958424,1,0
282.78434094658513,120.93363489490956,0.37922652755212727,0.1289549365077797,4.92097953545019,0.07784900313782483,0.1892883507576267,0.07265428805258954,0.1515655633551968,249.19517932541407,687.7785189018484,2,0
175.41878113737866,227.94582557521917,0.46983645961583964,0.18119995691806262,6.046721757662503,0.0475839873857067,0.44065688939228015,0.13630441637978838,0.47480786667038477,697.7785381190847,970.2529532143024,2,0
211.2699621635856,354.17022935216073,0.1628307792690901,0.05961946590344998,9.550354854132326,0.07323652765669342,0.18145833530797864,0.20726099782749455,1.0649261179554528,886.9992174010633,531.9295546250901,2,0
264.1895866654261,343.26656524748626,0.2386550301000701,0.06923777604874769,3.203169582887069,0.06687200565230651,0.29458005616787025,0.24624888432885622,1.392660292863932,489.93334847197684,628.5901279937976,2,1
39.920630196300905,446.7546001270078,0.1425822342098576,0.04881690853724665,0.5393280606782702,0.026569521145400322,0.12228493830513659,0.2955266039120625,0.25320046568092425,412.78943464564435,507.0057835223954,2,0
75.29914005581492,261.67742416251855,0.47635866753146616,0.1478966853797924,2.655629708125229,0.06255721861766342,0.10158137456778853,0.24640599378032194,0.5374516566142588,835.9448483354673,657.3343976357278,3,0
100.26136102563818,366.70769254333214,0.25595696177269917,0.12234046970333544,4.039942899772911,0.08993115269119095,0.3174944652758343,0.06694617820661762,1.0759830302232514,809.450466929644,325.4693046818519,1,0
287.80234484636037,287.4010362283906,0.29454865419250376,0.01018622796076066,1.4212292056977642,0.03363524676465179,0.27147294967738833,0.2635333907629273,1.5522088823541556,364.62942238598964,989.2976271319225,3,0
168.44933084545963,366.0600924571567,0.4792039273527341,0.06985226775149916,5.439744755571987,0.04003502329380873,0.18547414510362784,0.17292710519127008,1.5855447215136866,342.65904547538497,139.12695461839212,1,0
211.22146444294364,137.25672758651353,0.12662061957200607,0.1940763997923847,2.339384595963476,0.03152469561834691,0.18447324581359317,0.10741799968067384,0.7195811859773581,288.5784405455837,760.902285266601,1,0
284.1041318404322,171.147511290863,0.3969838345557981,0.1608431743915943,5.378710554812051,0.0992201920504037,0.4234293618968872,0.1282464889744233,0.7969481373400348,500.5328277019455,211.1626333330949,3,0
13.124039469148826,113.52579965927765,0.1524820476684592,0.07820138437680534,7.550811886722139,0.010490029000551444,0.17030129486166556,0.16562320070228495,0.2534926648800357,705.4731097286544,414.44518215676703,3,0
54.98206126803208,377.9777854117316,0.4737209110436047,0.01596690460550378,4.854149574529832,0.044952148442084484,0.4245730335890681,0.26312225650367543,0.14804049248337514,483.72938706096784,898.6984941496914,1,0
87.78051163510726,110.34372450710839,0.2369984728616284,0.052205289446395575,7.153879345182433,0.04890335001801512,0.45846329206747966,0.3027427344691477,1.1859218633012047,744.0846450150204,923.5054837506599,2,0
231.9284321244861,432.5575271158087,0.22209953716181238,0.0631201256367708,7.485671007887975,0.011419420932421952,0.08985194443090408,0.3534133723132068,0.8635541958014272,324.64412374998545,195.95817670413317,3,0
135.05516464373534,173.89507536125518,0.4187839402071696,0.15559132142752405,3.5241847678264397,0.04825917044335359,0.1996597055792479,0.15434531914818847,1.3393405378378367,900.2553766888949,164.58493466480587,3,0
73.89069112739011,244.43057399001734,0.4502115657401409,0.17149945826267443,4.995289884612926,0.03755064298978757,0.036128121305102005,0.18982121426177734,0.7241791854788446,500.8221072679395,174.55126108828497,1,1
114.65459900301484,143.248042736586,0.22604320683198018,0.10189118196594643,3.7452821177172244,0.010710254589976896,0.1769466344392847,0.03955963608309705,0.8250048576723338,224.78990719449678,472.4385889486635,1,0
166.61684576205576,193.48481640460042,0.46771617171894897,0.14041856196025362,0.8866614503107151,0.07166239687607324,0.04436795608021776,0.2058841278948519,1.3352621917447003,372.00383926953356,852.2853146690063,3,0
21.318025610354272,352.1879184677354,0.46295204987812666,0.12186749268667739,8.363131858773226,0.08643968926184359,0.22505688275111715,0.3683441211985696,1.317676813962069,638.9398629105215,671.3854359124148,3,0
16.184298113632607,395.917927369478,0.34396255276609267,0.018441326900353862,2.8938357468810265,0.037442348350377935,0.2833593260967062,0.21067633924438253,0.7167350526205768,955.6538028524324,793.6845468284267,3,0
12.78991299498199,361.4195084842038,0.44589660130898146,0.0196880698373791,0.5236995517099172,0.05815529856131704,0.17297161159648072,0.16608093377781405,0.19449643578171066,468.0215128090782,799.6429399928022,1,0
59.35469099080036,99.72121472688922,0.14043077629643952,0.019318943291111536,8.161185308517664,0.08911627903237983,0.2869247153665689,0.13445330666127842,0.528093772036293,766.7462706271533,254.45421205296662,1,0
283.41486412446676,159.9428542599553,0.4916233017963265,0.045718759939547916,3.151163926143557,0.09636008195764277,0.4566454005909513,0.26761744731771225,1.3904827475315484,495.8361336380795,456.20905078377683,3,0
280.83320990991,426.3588632464127,0.44817295490816866,0.05435733364434473,0.5757586761820139,0.0271501552758499,0.3470823911832878,0.06774263431780843,1.3042077073067817,920.1289514640209,661.0916217313442,3,0
82.0969619427332,464.37083117853535,0.41875360489382674,0.16831803006943336,7.1058207366176145,0.06391067080201815,0.261634473120224,0.3355376170702369,0.7689023491662372,656.2209594193469,641.6471811589131,3,0
26.4695332070423,252.13827165020427,0.1944686072981445,0.10256565985053166,4.84990034397356,0.08960479725542675,0.12404006382559701,0.20596071251836742,1.8695124494453546,577.3485743805109,328.5423315494088,2,0
105.92957062444727,417.3145347013032,0.1431781712907539,0.032155175288454366,1.614753760779703,0.0109315369736119,0.06152256229833315,0.33138269253763775,1.7681942117803449,866.451354627322,981.3528240560947,3,0
289.3586411170282,486.62341370232656,0.10323553763499733,0.16562936355114324,1.2711891163052325,0.06240063824349472,0.11001864037417926,0.04450986541481087,1.9984152725781266,898.8020715067702,389.918008231078,3,0
105.5511765133133,54.75047359780347,0.12391097177160137,0.02478922746671276,3.4665658152782486,0.02412255928890756,0.40387569195179845,0.11377861598976599,0.3557259327244887,971.5360778804842,812.6863549552114,2,0
282.81969665644925,339.6450987689592,0.4363599200467615,0.01706919565359037,6.054893738905865,0.07372083084534559,0.30393303073418193,0.3406142887745856,0.3840519186729078,346.06265350296565,762.7407425026445,1,0
38.81660949158044,255.6743124420327,0.24890380782212926,0.02613475616384097,8.670969479391756,0.05092461746925994,0.4005978454142112,0.3721343641309598,1.5834264658069421,325.4377662015045,978.4593312748746,3,0
173.0428137110031,175.60605621184146,0.34287868025536505,0.06248392477480865,5.41458593461673,0.0393516505825435,0.2894112638058232,0.27072613155485475,1.8843341402001177,673.9733470510389,676.4560576392145,3,0
129.07618004701172,332.99597263912176,0.3111066361937299,0.10063432972811832,7.244672932677436,0.031000212280759776,0.36559387832147333,0.09169770606688062,1.4775578181051583,987.3876447746255,839.1364409933593,1,0
295.38617657704623,341.75579853023254,0.14593811074584534,0.184790501928565,2.4574000205263404,0.02200309100922912,0.39604211810954726,0.24010443465436548,0.35435827827205846,416.12601900697445,191.5038379474673,2,0
174.45878505603997,353.6543554305047,0.2195138140107723,0.10549522450205097,5.250861613236299,0.015601234993004899,0.43332367485961226,0.2763964950594187,0.8493118690804118,315.0655156914935,500.3348375849876,1,0
131.08507590564608,92.48830625396272,0.4784582930723523,0.1047900182697457,0.5141752357259817,0.037885249120803564,0.0997238802419486,0.04704041170354686,1.0395733434243852,249.63123815203065,840.9505712511718,2,0
185.36037058670587,155.4856832893721,0.38084434929447797,0.044714812413201174,9.65193783602806,0.09575989502986001,0.22274155942517568,0.21424484204904723,1.0603869266732393,941.7616090935246,190.1358231905913,3,0
189.87908249294705,497.36965635778563,0.18475728926052779,0.03854777776417007,8.488742443651795,0.016186463164031425,0.4072116082927539,0.16862161810565154,1.7846655212776104,493.0583904078727,92.4526892167325,3,0
63.13844228866323,112.19914017715095,0.4742201565592016,0.051616745609931264,7.470039637170481,0.05847135297455826,0.45640306027625743,0.3193346796866499,1.7331561701512268,338.1117779822289,700.7273154651979,2,0
124.17499195883056,323.01967524692975,0.41126612018853714,0.15481695599418538,8.57983266787256,0.02345287351374174,0.30862789527270146,0.21268470921551116,1.7779278183651315,730.7046174319415,512.5574557020843,3,0
271.8493020714735,441.13538110784805,0.48321150247625544,0.12322108905864794,3.490760577357223,0.06788524205490434,0.49547239256706294,0.35439103835662866,1.831801300836798,996.1327772950491,248.46921146508768,3,1
268.77619812853385,372.99956118185634,0.4569370853758137,0.14831924382561396,8.98597379170308,0.08973901164982084,0.23230730251433168,0.16849703315715303,1.3273084087667228,473.55853710591856,550.7015347090032,1,0
87.09701682505933,312.6451410064755,0.24952226132985197,0.07457668925868248,0.9298138675081142,0.010752549041501703,0.38716759000856027,0.34931186069269554,1.7956245371956114,446.9077898667866,624.4835148852943,3,0
205.3426738812385,438.64511436369156,0.24043107008638565,0.0844967909831229,9.091689644650119,0.07664746643580411,0.13268030422744545,0.23842776666989904,0.15229007895704028,739.1292947788269,579.7331533606709,2,0
55.04533849927707,186.91126220742004,0.17871177528143908,0.12526678090813775,1.1580053652663447,0.07443239333760172,0.2512831988592039,0.3283798444276137,1.3757535330233537,204.4412597139856,364.103545994607,3,0
290.5448667663145,379.7973663329169,0.31864597599760486,0.059702371545952995,2.1502964728743414,0.031091069157395013,0.14106220264717048,0.016796272151027136,0.12203022750828468,893.3272012985069,387.48397702440775,2,0
294.46097168915713,490.3431782938281,0.4195537159006384,0.0960646746771219,1.6149276269841941,0.041658117655385234,0.4570106957268918,0.1100037869060013,1.5887677557981892,288.1536438879986,702.1163061935724,2,0
141.6527212019335,413.96123255543694,0.4839486980315678,0.13275763719709574,2.074980396601977,0.08703432318317657,0.44931065623052474,0.2951427081396428,0.4222968019865455,988.6321063046901,841.0517470816851,2,0
156.78552883105732,493.1489912621606,0.45722774174154535,0.19342718970703524,8.848929396685836,0.09173770828195536,0.24467392779212382,0.3317897510769727,0.5686426871621685,464.13198552453656,645.318207394374,3,0
280.4702054619984,108.71109479537353,0.17457004704444934,0.08701306848888947,1.718490286591867,0.033912348721455994,0.12626171246861279,0.08479773719971091,1.5103504911496102,830.7516663824001,925.0294909591424,1,0
153.9025661367358,263.16138978957383,0.2831279681259714,0.07145358248883042,3.867833276361121,0.06010140701912431,0.19754895110161777,0.011939535612108984,1.6591603260171885,868.1108032073973,311.5506050998655,3,0
291.59744388616775,384.36442357695205,0.18723175012040258,0.1081217493320731,9.753333149180145,0.023780946652752547,0.46673020629272294,0.3753246929386103,0.6336432709889204,563.5153669535703,232.29748575506895,1,0
264.27882853833665,447.57899507641474,0.36930426682630324,0.14611677389038355,3.7153613849001004,0.09752296519310304,0.3996551206476927,0.27353363225505906,1.2123183424054114,441.10165713058166,260.26116403312477,1,0
116.30783057264212,370.31232151671077,0.4490992457795481,0.18950477891753784,2.186708224069851,0.05881215201569118,0.06270409395113535,0.23091677039647038,0.4291953548122671,891.9296707661136,215.14844971445257,1,0
170.48591231975377,52.103904889196265,0.13437826104928596,0.042845705514013045,9.832604023440396,0.05957046087429247,0.3358302928512616,0.29818895634731135,1.3426091060279355,494.6291181731378,417.56815299699286,2,0
30.730684886059663,66.03891889827082,0.440031657067805,0.03860834723383353,4.564715133912821,0.03806948268513807,0.3629287820095074,0.3536837529798109,0.11274543124010017,405.19959371770506,991.0130202771293,2,0
172.1576172817344,219.0209959841145,0.26241842972105106,0.062044992866114625,8.980838617342297,0.04035106633735233,0.06202932847250755,0.36013462787663475,1.5515045639712817,936.7518853400312,978.7626016550852,3,0
271.6290430193329,288.64347262564104,0.22110539852988065,0.1206186451201247,1.0530899411241486,0.013642221381309183,0.2375332213739442,0.139394782237865,1.8781077139407358,242.96725962029208,843.7017826144041,3,0
45.08480831368444,204.3630560244901,0.10152523536340237,0.08585066602000391,0.5251687629983923,0.07359488576324483,0.35998302763600876,0.301772855875863,0.370470800539521,417.8995008117217,949.81244959555,3,0
209.07579513438884,72.22812251805973,0.39786510215874404,0.03051439302733635,8.813467504810776,0.06025934030442664,0.01504798399183236,0.3544105724339876,0.9612100254508418,456.93347783888106,947.962494383806,1,0
161.29166374141917,164.79767083133214,0.24042774573316028,0.1688399498581126,1.986509300942118,0.0786140177073577,0.22380013796799417,0.21511543431057378,1.1075838260425814,363.0112407128968,459.2604459448598,2,1
161.3877077740572,355.4798243665644,0.17728825112464752,0.04817252294018519,0.7904576922720453,0.02938484988062664,0.496113876555932,0.15577661537295798,0.8263212830002757,231.91389722476492,245.4538949178467,3,0
14.468104435282598,63.94948114260736,0.4807750731171252,0.14482131321499164,4.253568407558683,0.021392402220554177,0.12562975862070497,0.3243085351655833,0.2646041441388229,931.2594410271007,300.7258755554909,1,0
116.04080017238348,334.5916058045301,0.2183185759205636,0.1514465926791032,6.466512727170429,0.09487358386792082,0.1878702021121609,0.2727721738642574,0.5688268109818392,269.71754647609566,95.5595134671,2,1
108.568709892379,246.79748022127248,0.29436040398256874,0.19825321647530528,8.068133857384819,0.024782932027501196,0.04315768939178817,0.21394953767880295,0.15865563726237566,795.5292498306102,621.0715708345872,2,0
107.77706680820623,107.97977749626276,0.43708081859006576,0.16131622117851668,5.558550025596841,0.05147035440017258,0.399822373057796,0.261438415535823,0.2816124046379542,926.6981022551306,840.9103641579374,3,0
75.962810205745,439.4979595760217,0.2273284337608421,0.1616098233143936,4.368881631212966,0.03328098189055482,0.11750867784338409,0.13341995888411792,1.4154050435291123,580.5726171527267,199.63268359008924,1,1
75.13549588029926,158.44018973082473,0.2751558724214361,0.13184388597530056,4.590781235389498,0.02867149093144824,0.267541961193882,0.3665363326539801,1.2281816898741023,871.8740392750753,119.22839924680709,2,0
137.13534435774054,404.99207104548265,0.262809808134582,0.09573229773638268,9.986485988796662,0.06997250597870332,0.29973080237711025,0.21178186201881347,0.7972049846767504,619.9915909653722,279.7384901399675,1,0
150.13307809515368,476.8808999529731,0.3601919821729742,0.13629050216724972,3.234195941894118,0.017074635747839864,0.3849060579851412,0.31609852069796407,1.5923449072277422,818.4302041827651,299.20950178708114,1,0
134.4583993172223,258.24160839192655,0.10928034334004506,0.029627021924554617,1.6943748225032482,0.043375120816329146,0.35054516084244614,0.38496539524477885,1.9534438137716166,516.576532911604,526.9301290415176,3,1
153.54674371035742,288.7080380027704,0.39737463116865734,0.0548352246104516,5.466816851673685,0.042844903547196486,0.3577608459998502,0.3318819760636112,0.3196431154332693,907.1413350698353,643.9838157205969,2,0
21.980231191882964,489.6437876578033,0.1278350744734926,0.07652850214942307,2.1803987952572945,0.06629577490238542,0.27029143755726076,0.17619777706551923,1.555817877113304,943.5497047170135,585.4078139389264,2,0
243.79790345748424,285.85103041888254,0.2914001761276253,0.13128084836444684,1.913974969980386,0.030986283837595954,0.40584717708929624,0.2544959905237744,1.697664378138651,725.6408566066315,399.0836782813806,3,0
122.4107310873496,290.75633427486036,0.35301312165031307,0.07252353533004466,8.185342433902811,0.07207506445123577,0.4824172544244964,0.1722555602907594,0.6823936309823718,979.7840615053599,829.2195873489568,1,0
139.15696069040013,139.05601110596749,0.2794790779027533,0.15871326188393928,5.724180390421435,0.0974010221077463,0.03329980364261468,0.08065986727267803,1.3806745796986857,480.98254887686267,426.81384771051967,3,0
247.67872826927143,301.2416813302085,0.2068724672405312,0.11947912078508793,9.614248085723723,0.05360393015307345,0.01966076901792791,0.043813050906033386,0.689585049536859,377.5103910929706,505.55989718264146,2,0
266.0783575796306,428.864210086705,0.3992503632894767,0.018322610878590675,0.8111346445325405,0.08897651507017412,0.2613343719995545,0.09027261624417574,1.9455702395672752,811.3226040463542,505.04188806407774,1,0
214.31119164168817,205.13556137467702,0.4086649289401063,0.06816128324856481,2.7133264047158976,0.030109822845270556,0.1594362906355372,0.13100440213620373,1.9940759032486806,579.2136629500671,314.9975888953833,2,0
171.68464014605635,52.82885599190955,0.2053141666476801,0.034248577476806444,4.836864371852213,0.05838113089151053,0.09887723099742271,0.06594067734440123,0.6343049766867854,890.2090075380153,424.50776094917825,3,0
154.15453378871197,152.41328095677557,0.29095851502485526,0.11588320737517964,1.4972403907334086,0.024437769121299056,0.05328511249851968,0.14806191102186936,1.4152198112177738,373.7904155562742,57.37204260387425,2,0
12.218273049239066,318.1170179307863,0.13121873598235223,0.18601372537978753,5.664719184588815,0.05485916301352046,0.1624621803705984,0.07132020662694338,0.4025806460530089,580.3642457902835,608.0383816300706,3,0
132.0471717135555,467.20027147295855,0.1895810390319277,0.14106281616661684,8.031180283326622,0.011353604992953606,0.13541374352231125,0.012926978360368921,1.209986152718138,470.57394338703,233.61278316828142,1,0
257.2432951776334,200.62856039889238,0.16394197406257277,0.09159960001934246,5.678266898133884,0.02737362088706507,0.08683331741173393,0.11020884634299337,0.7567891761787342,936.3540602281008,509.18647554053234,3,0
107.03641345302508,297.4569690284883,0.27341643950128136,0.13688338147822662,4.853242733772456,0.09204272320635859,0.20958999130685604,0.3800314852993317,1.8936576804044778,408.9143080979148,954.066775658976,1,0
94.84935577446998,233.14740431165964,0.2816961763093165,0.03369368861518253,8.09356871723391,0.026558211919223196,0.4286474631409446,0.3182044694577629,0.7048095675326482,456.41141092896544,564.7502246549222,1,0
279.13342715234165,230.4943993814133,0.37620586471866313,0.07295073864126805,1.111908020539606,0.029198929529457865,0.12136787986419523,0.14733433743870084,0.7604208719875737,398.2609987831645,856.2896715349973,3,0
12.20035264207402,321.27582510304245,0.4243357895522396,0.10952759745258485,1.3928310215218054,0.05641918171316158,0.08993436265194041,0.038158183520696956,0.45612747091138206,344.2846336241944,546.3917146233616,2,0
278.6792905101238,282.9281335070582,0.2889732475552137,0.06378518182755298,4.292228092550259,0.08854041248555863,0.4297252515846018,0.27545592728066925,1.274300364684753,921.2476778065405,474.4081914507604,3,0
43.02135198518341,127.10595910586187,0.4742958896794601,0.15679544664364836,4.764715149433705,0.023526851459446343,0.10762278705580927,0.013190051744567988,1.081487231054074,623.0599244064363,245.09750340577128,1,0
19.865720390850775,396.2497001922761,0.47199209741960446,0.12974012591240408,2.9953686342014545,0.06612215782921833,0.03821679597945896,0.2770951650282006,0.41221794070922035,555.6125978211437,216.55646586581,1,0
36.72283537401165,211.2246221741496,0.3206057140966795,0.1382592577210703,9.680470797627109,0.08928433914694889,0.253777126889171,0.3102756412487749,1.055164911947439,853.5394818468001,95.5226903302269,1,0
221.4073342326583,468.8297606504617,0.3027216777586388,0.07525384284787162,5.045953730288476,0.08476026565084656,0.08631492192635017,0.33020358411857764,1.5257408766112646,760.0991968673067,461.6211584905705,2,0
276.1138417872787,140.04171617489158,0.325100396695419,0.07753318639859078,9.456044581070765,0.02809565630683212,0.4685310010786233,0.1977203838558119,1.0464927801195287,657.525791439457,269.42691220903123,3,0
179.74656740255907,211.78806873210337,0.13832540865200504,0.03199536416449588,5.897819826240293,0.029921264009662905,0.1698518424608403,0.19237094882471042,1.1521440912538488,956.9158718614382,481.71591698186535,3,0
115.04372012046544,184.89877424597535,0.36898675324431063,0.11291642662479483,8.985725584089854,0.057058078494231175,0.04524603071210777,0.05070509883460542,1.1070464487659755,929.6571293399631,556.7386390450494,2,1
78.76493991742238,395.4603657274492,0.398514709709444,0.14842315116912824,0.7021453231723854,0.08761521006507118,0.3550382062768279,0.35478246239652006,1.1436198716801984,256.40992001072124,429.407835912386,3,0
16.958342942309187,492.7885812155026,0.4114933128635285,0.11869479180083567,8.346628006766517,0.017495986144994105,0.039027300671295825,0.1812241365403869,1.299893878846441,557.029046711692,910.2046950471282,2,0
154.58897669401742,177.7726655246837,0.25410885515085047,0.1604223530366752,7.354289572938148,0.07280465476006606,0.44397822722210584,0.2990662504911039,1.071755401902187,346.3620067302543,159.2182520655087,3,0
68.50360597144368,124.83466993247684,0.1710422246700718,0.19641451627727544,5.479269210461201,0.047747918208875834,0.3119562349248896,0.30888031534941035,1.6168474588602986,923.8899805112392,576.179537689827,1,0
94.16243819703394,52.177539414269475,0.4899453149708083,0.17952405852284556,7.863770168895005,0.019371108112044358,0.10836297849227218,0.2644120592627647,0.7575407201047142,266.6611575285434,136.33855566202456,3,0
184.7546403263169,299.4793777871849,0.26882778909067984,0.16379711490712473,8.324016071434821,0.04898243058261551,0.19215518928468772,0.364365566101477,0.1709840677190397,697.2827343648787,918.3653126526698,2,1
266.8705842078702,449.0321158254084,0.1682771955302642,0.09981174710725602,9.478600632424856,0.07682680880578706,0.2781957145320376,0.28112456750574333,1.5529213645043676,356.71247767283677,462.9949944482028,3,0
242.04604180180922,121.8766031281154,0.2690699827823753,0.15196347403287785,3.8020616730317487,0.0374023537061652,0.1580887155051217,0.2596756093333593,1.672507787738313,212.36971768604383,794.9059198319379,1,0
143.41576870923257,486.30532834957273,0.4765230378656856,0.19656194485324907,8.567311437620981,0.06614702052643358,0.1428148413061467,0.20864723059113555,0.2372412011387047,661.5148673110905,968.2739434632875,3,0
260.63327174201584,158.66809439445984,0.30906920902583745,0.07064677590874902,8.059903940001675,0.05029289133033823,0.3322828209548458,0.2923865069608515,1.6568480866382869,761.1095549564203,845.9347661223075,1,0
49.73219771404874,254.061158579948,0.23322429401203126,0.17302717689682895,9.072747256985231,0.05893852003956393,0.484039246212134,0.16469426653599878,0.1975512897674071,279.5871599722569,560.3580655468335,2,0
296.52224573936354,264.28224540500037,0.1176210532912843,0.10247542112368005,0.546922318784969,0.06006983259811407,0.4019493007282464,0.2528453467359848,0.8372892432803617,796.0464974808253,286.90348624981425,3,0
233.27390676123213,221.41128079633313,0.24475665106792635,0.01330402149487283,1.922541035130915,0.09475526105107436,0.2671142841675716,0.16043376960125535,0.8464239616783988,857.7512265276793,986.5130002328181,2,0
238.14793504108636,258.3359472944491,0.24937128037839337,0.06116732489256804,9.191709634563273,0.06484879769839576,0.45469241836536634,0.11734915662986492,0.9926169001375337,640.6231982836744,596.2044311856962,1,0
107.39632170566622,320.7108538546855,0.15268632752490446,0.13321501492513124,1.4716538099043255,0.08809573249509531,0.121896000265884,0.06810046587293628,1.0678960474884414,366.6191674031696,202.38670563096082,3,0
199.4479650545452,488.4757156604487,0.4302543652721007,0.13857927856748484,8.361128180726844,0.035030482869264426,0.2360579826677441,0.21040980816367402,0.569901837175231,572.0414329430762,765.7875373471285,3,0
204.47626247606522,238.25415033653044,0.22943996188656013,0.06816750150374998,2.7710900218253793,0.060016296007516914,0.055850480416417936,0.3374038987909043,1.54389047101253,994.9221563022269,790.224884278341,3,0
236.8953161295661,98.81069982723433,0.437566063028056,0.18441411765000426,8.485408601984998,0.06022513527390569,0.2822445545515101,0.3108557262542554,1.1202377909756869,618.7354152106734,896.1906343959276,1,0
133.01613386471766,475.7012004088282,0.48845046357081157,0.06054993420598367,9.760682728839681,0.0539989314784999,0.11274388532688476,0.15779268416214592,1.0855940668454223,259.568470289605,631.2399061153549,2,0
172.43316112690806,152.57002808846926,0.29218567227401593,0.18953032770640413,7.532187839861433,0.043071716969654956,0.4363176076123141,0.19523084764162282,0.7908637020329538,670.3294769753945,855.6190953163518,2,0
241.73189894819558,380.87780528309366,0.45022724014492777,0.07809896481918291,3.847781183955906,0.059940008357267115,0.3928313710552742,0.3517182325479374,1.7400529125098927,676.1368678071049,609.2972695884646,3,1
174.46184639608245,384.0636895548099,0.2741767188338605,0.12594656472320967,9.24664225160054,0.08120368212969105,0.20989869190665875,0.30015230011334426,1.032133821011438,731.4849182265308,459.1839897442256,2,0
155.5813013494116,255.9974331853385,0.2540443520140021,0.17900729298332818,1.2943983367022112,0.038785124389689986,0.4384432188949282,0.3622973506187525,1.3381884651744984,829.3530176678807,803.5589996114898,1,0
159.17223048729906,369.33143009948685,0.3636315582701135,0.18896239995058833,8.632567794134369,0.07499939335010491,0.15623247524073,0.26809781135829197,0.1381133461060038,670.2324900025211,866.0666467521812,1,0
277.5500923682812,81.89872306233954,0.13655969221816033,0.03760463937818677,5.544965171456381,0.041191168811111054,0.4320579519675611,0.3276191080527572,0.1491045439473084,326.46473050714457,686.7141868860314,3,0
78.64850691060086,400.7776839276718,0.3399808038178388,0.17209012239331295,0.509816621623074,0.07304523563333637,0.26363192615411724,0.3079658746388177,1.9441949550180853,805.7628064281124,506.1118860591723,3,0
230.60362079187195,263.3277639652787,0.35805873967041646,0.17307476266046154,7.4104565934065345,0.052411689752364155,0.4601090565397712,0.39109698645373614,1.1014485950205433,543.0970245835156,924.2547968847002,1,0
41.72977518540664,333.4578462098838,0.31345186175717765,0.012303481254126702,4.971702664582248,0.03182832487153541,0.3251108793143552,0.14633270324063732,0.597824142704958,244.73686206830925,855.5319506091829,1,0
197.73236977711656,355.2292886584937,0.29470576489175515,0.039694316774975875,4.788735811577521,0.030516929062388433,0.17737166746411348,0.10115623708833359,1.7062883303311622,769.2557361322109,174.76618781721567,2,0
228.1700810530867,134.9853519772833,0.45513331945367075,0.16663234437017746,0.6701251792505544,0.028328993230326074,0.1890392088088696,0.38872451154405957,0.9733595589525853,887.4182028371374,235.23684224927788,3,0
224.96470722963804,255.33792762287226,0.37699788768700637,0.05219343039752213,7.9618835335738884,0.07124390807043546,0.08712216272395855,0.0943360408002267,1.2768122781118498,954.0388394868581,508.95334492540934,3,0
276.257573844462,243.45857566397518,0.39553663938144856,0.1361851699133392,6.033646067025646,0.08339231530264149,0.26053819465159755,0.17909543744972328,0.9922385950609837,859.8414075477755,602.3672935578871,1,0
299.34732570036766,412.4972454400649,0.1399644206144391,0.056813099777088316,9.997519289647245,0.09590145123329981,0.412123509550088,0.2836705036741835,1.5741725021779898,998.6466949160825,50.36969874911348,2,0
244.31161786521304,134.11186063504778,0.25917184845290697,0.09163239102749397,1.1120264046562947,0.049406741829315884,0.12105956024378954,0.06938481458202359,1.4510821664696838,933.4123433013915,740.0018030651984,1,0
117.77274926452525,395.81680598960816,0.1817847563643038,0.160617032789553,7.998439451084515,0.038183880713173,0.139681263509451,0.2308271616261689,1.5113787905562752,612.5187654294472,474.4505623177675,2,0
41.79078258373099,283.5112052319544,0.37067630510527294,0.18530051152768082,4.993037818244994,0.018805978816232166,0.22560804133457246,0.3634127247464411,0.5425387968869145,752.0180848450558,955.6155868765231,1,0
279.0032959896744,150.1473452556939,0.30442738053298846,0.11720157678463844,5.295224747735707,0.023975523445862543,0.03447038071283233,0.3257221053570042,0.9102235744288125,730.4021723205959,109.11383217607394,3,0
190.95833150539877,83.22073937754519,0.21091530630935995,0.06793273207579176,8.982927157909499,0.034547087499495845,0.36696572807445804,0.2474844789040557,1.722493848580819,543.5538205386332,835.071643463506,1,0
46.827066332424785,249.61767232001384,0.24251695977271678,0.042693367625622716,4.341760312556334,0.08761879800370605,0.2433867171865576,0.16510808820839692,1.21917759145266,303.6119500792463,78.97095098797804,1,0
263.2772722043738,445.0685437407348,0.2735487683450231,0.03803738426871983,1.9406212723248033,0.038468632391708814,0.42113858413286226,0.3747279463922249,1.5234709334230023,539.4955906021027,625.4583248982108,1,1
21.352312606170557,221.77928582163142,0.3193484356422599,0.09048921034095292,9.85807841642494,0.02686479181200798,0.010784648667425949,0.3085201198123687,1.795950624583939,920.4902731799691,268.2719411179177,2,0
276.45778702876555,151.629756178102,0.4601179894633527,0.08453811068986991,5.803240315777585,0.08246417465502072,0.39489856483441205,0.11512952814804225,0.39217841917370744,920.6784357491298,616.3107292650127,1,0
42.2037730139632,189.69542530080852,0.3753618584665416,0.125863524748635,9.89763996708725,0.014204891495891093,0.25154357917914627,0.0471344977154665,0.5788414988999766,779.8128706142934,973.6713158995601,3,1
265.03904903501893,216.87762308908674,0.3520644938219406,0.05623522573794777,3.238569658702673,0.09197980007299866,0.3320339378838853,0.20845445740792537,0.46392470447025114,637.4467135365884,481.4682410970001,2,0
183.83524735533024,67.98952980735918,0.4163295799411729,0.07561668857827114,3.137976047700378,0.058154250899580255,0.012189288994497803,0.20027852576882488,0.8116290668502621,474.01517686324786,928.3642868064561,2,0
53.92935513311528,467.2137211162767,0.24646565651834318,0.19239413398120228,9.463986818783807,0.078103709920485,0.02315447469418608,0.32815007933530704,0.8303108507762373,659.6919170626263,790.0329583555438,3,0
183.82687206554778,484.0800247415277,0.3893879761455472,0.14892949907225142,3.108472773981752,0.03890484815111714,0.3677076410760475,0.28544897073950415,1.4904737176813376,227.89046305318826,887.1019423767239,3,0
217.59725253867816,374.73909851789415,0.38481246560658744,0.01916383013537101,9.998909373568841,0.08983998897810633,0.20625746828912808,0.36656530685027694,1.1174704870726244,404.55582708024144,711.9381700909141,3,0
244.00894719548356,97.69581110151661,0.38119011630920474,0.14781803219223802,8.2748802193822,0.03530767461424919,0.33159278529251013,0.1555445767967559,1.7436205927538675,796.5970661887555,920.103330635626,2,0
230.60848846125032,276.0214924152556,0.4217290810713167,0.1653087951671582,1.9148278083348995,0.026677498249709525,0.08677518811654322,0.30695163174905765,1.1821112739403594,267.50346813700753,988.2888972012535,1,0
27.45112241101716,163.54915645892066,0.49920626693431946,0.15861605998954717,7.609606550700349,0.07556235991378545,0.18152808450453065,0.2027013795881249,0.22943005507406733,732.2121453328845,527.1286120113842,3,0
22.136906039366714,489.8238717713968,0.48075123784529594,0.012981256050657086,5.979012326672829,0.061401149736909424,0.2840590823594792,0.26027068465721265,0.5292554633573276,688.5668707464306,990.2477243367892,1,0
279.55204886734674,423.32122531435056,0.26506180050412,0.18932161175473622,6.907574152074434,0.06908592084643524,0.1440882058226871,0.22444261287106976,1.2050955781133128,717.5601449991295,919.2622164602827,1,0
285.5573429957937,382.19882093055486,0.3994795864934816,0.1903293236583883,4.12573080245714,0.08052296406772438,0.4597445012701067,0.07531208879892223,1.3614368874972953,465.10663591531295,713.6324909503754,1,0
112.1179945182825,57.303704025031905,0.44500395740400267,0.07135836850666635,1.0315608962151253,0.01620238156678497,0.19444212372958206,0.04323477458867362,0.537765428883022,565.8564950763167,816.5674176522866,2,1
112.51744134808453,214.37340414253944,0.4647049340877736,0.19477773123238504,2.274129016475069,0.01754205518606229,0.28923795851935774,0.3626087389868873,0.5412975746676113,623.7860838076114,542.613356233559,3,0
80.14947823839609,159.6175475834479,0.3308987706364862,0.19610656813394292,2.8182241073624836,0.054312976000358906,0.07130345254325472,0.04728265221040101,1.3044860145809667,662.5676995163183,926.4738466939743,1,0
65.47759106005145,142.71844875396812,0.2887256443540269,0.18920131001746632,4.983096126969413,0.01849382284600612,0.35628404127885416,0.09904543429976247,1.0718331764567552,213.97340182901897,76.09295778686177,3,0
95.14356726838345,310.1797731998832,0.4290273823886511,0.15670644221343996,9.898660479491792,0.05839896879755034,0.11098970065451741,0.18136430540883106,1.3623946161401435,675.2045997572396,176.88695607454025,3,0
266.80059466570924,90.52250971739807,0.4245260059257657,0.1238335443404154,8.105508471291436,0.0407968028449355,0.24669500292277752,0.016147328402377235,0.4983905203060923,477.017773845673,986.3094468177718,2,0
100.45745705669033,367.93694728800284,0.25403412052277496,0.053058304150796785,1.7649835039255928,0.06567587995420715,0.25725327649892427,0.2543002551296143,1.4070033086676588,891.0709573671231,478.25228811520697,2,0
141.61350356240936,210.8870189533454,0.3013274915900198,0.08229424219629596,4.852267532277524,0.05220626014172685,0.2456787163497823,0.21919657558951527,0.10296415313631108,683.2061744645182,416.2656062990015,1,0